<mujoco>
	<compiler angle="radian" coordinate="local" meshdir="../stls" texturedir="../textures"></compiler>

	<asset>
	 	<mesh name="robot0:rg2_right_truss_arm"          file="RG2_RightTrussArm_vis.STL"   />
        <mesh name="robot0:rg2_right_moment_arm"         file="RG2_RightMomentArm_vis.STL"   />
        <mesh name="robot0:rg2_right_finger"             file="RG2_RightFinger_vis.STL"   />
        <mesh name="robot0:rg2_left_truss_arm"           file="RG2_LeftTrussArm_vis.STL"   />
        <mesh name="robot0:rg2_left_moment_arm"          file="RG2_LeftMomentArm_vis.STL"   />
        <mesh name="robot0:rg2_left_finger"              file="RG2_LeftFinger_vis.STL"   />
        <mesh name="robot0:rg2_hand"                     file="RG2_Hand_vis.STL"   />
	</asset>
	<worldbody>


    
	<body name="flange_rg2" pos="0.0 0 0.0155" >

		<body name="gripper_base_link" pos="0.0 0 0">

			<!-- nest each child piece inside the parent body tags -->
			<body name="hand_link" pos="0 0 0">
				<joint name="hand_link_joint" axis="0 0 1" />
				<geom name="hand_link_geom" type="mesh" mesh="robot0:rg2_hand"/>
				<inertial pos="0.061902 0.000129 -0.000005" mass="1.684558" diaginertia="0.000862 0.002401 0.002620" />
				
				<body name="left_moment_arm" pos="0.132 0.017 0.010">
					<joint name="left_moment_arm_joint" axis="0 0 1"  damping="0.1" limited="true" range="-1.5707963271.570796327"/>
					<geom name="left_moment_arm_geom" type="mesh" mesh="robot0:rg2_left_moment_arm" />
					<inertial pos="0.017004 0.006397 -0.010300" mass="0.160209" fullinertia="0.000023  0.000072 0.000083 0.000019 0.000000 0.000000"/>
					
					<body name="l_finger_link" pos="0.049 0.026 0.000" >
						<joint name="l_finger_joint" axis="0 0 1"  damping="0.1" limited="true" range="-1.570796327 1.570796327"/>
						<geom name="l_finger_geom" type="mesh" mesh="robot0:rg2_left_finger" />
						<inertial pos="0.024695 -0.010178 -0.010001" mass="0.081638" fullinertia="0.000006 0.000025 0.000026 -0.000005 0.000000 0.000000"/>

					<body name="l_truss_arm_link" pos="0.0165 -0.0093 0.0">
						<joint name="l_finger_passive_joint" axis="0 0 1"  damping="0.1" limited="true" range="-1.570796327 1.570796327"/>
						<geom name="l_finger_link" pos="-0.0487 -0.0258 0.00" type="mesh" mesh="robot0:rg2_left_truss_arm" />
						<inertial pos="0.023075 0.012136 -0.010000" mass="0.065927" fullinertia="0.000010 0.000024 0.000025 0.000010 0.000000 0.000000"/>
					</body>
					</body>
				</body>



				<body name="right_moment_arm" pos="0.132 -0.017 0.010">
					<joint name="right_moment_arm_joint" axis="0 0 1"  damping="0.1" limited="true" range="-1.570796327 1.570796327"/>
					<geom name="right_moment_arm_geom"  type="mesh" mesh="robot0:rg2_right_moment_arm" />
					<inertial pos="0.017004 0.006397 -0.010300" mass="0.160209" fullinertia="0.000023  0.000072 0.000083 0.000019 0.000000 0.000000"/>

					<body name="r_finger_link" pos="0.049 -0.026 0.000" >
						<joint name="r_finger_joint" axis="0 0 1"  damping="0.1" limited="true" range="-1.570796327 1.570796327"/>
						<geom name="r_finger_geom" type="mesh" mesh="robot0:rg2_right_finger" />
						<inertial pos="0.024695 0.010178 -0.010000" mass="0.160209" fullinertia="0.000006 0.000025 0.000026 -0.000005 0.000000 0.000000"/>
					
						<body name="r_truss_arm_link" pos="0.0165 0.0093 0.0">
							<joint name="r_finger_passive_joint" axis="0 0 1"  damping="0.1" limited="true" range="-1.570796327 1.570796327"/>
							<geom name="r_finger_link" pos="-0.0487 0.0258 0.00" type="mesh" mesh="robot0:rg2_right_truss_arm" />
							<inertial pos="0.023075 -0.012136 -0.010000" mass="0.065927" fullinertia="0.000010 0.000024 0.000025 0.000010 0.000000 0.000000"/>
						</body>
					</body>

					
				</body>

			</body>
		</body>
	</body>
</worldbody>
    <contact>
        <exclude body1="hand_link" body2="l_truss_arm_link"></exclude>
		<exclude body1="r_truss_arm_link" body2="hand_link"></exclude> 
    </contact>
</mujoco>
