<?xml version="1.0" encoding="utf-8"?>
<robot name="ur5e_robot">
  <transmission name="shoulder_pan_trans">
    <type>
      transmission_interface/SimpleTransmission
    </type>
    <joint name="shoulder_pan_joint">
      <hardwareInterface>
        hardware_interface/PositionJointInterface
      </hardwareInterface>
    </joint>
    <actuator name="shoulder_pan_motor">
      <mechanicalReduction>
        1
      </mechanicalReduction>
    </actuator>
  </transmission>
  <transmission name="shoulder_lift_trans">
    <type>
      transmission_interface/SimpleTransmission
    </type>
    <joint name="shoulder_lift_joint">
      <hardwareInterface>
        hardware_interface/PositionJointInterface
      </hardwareInterface>
    </joint>
    <actuator name="shoulder_lift_motor">
      <mechanicalReduction>
        1
      </mechanicalReduction>
    </actuator>
  </transmission>
  <transmission name="elbow_trans">
    <type>
      transmission_interface/SimpleTransmission
    </type>
    <joint name="elbow_joint">
      <hardwareInterface>
        hardware_interface/PositionJointInterface
      </hardwareInterface>
    </joint>
    <actuator name="elbow_motor">
      <mechanicalReduction>
        1
      </mechanicalReduction>
    </actuator>
  </transmission>
  <transmission name="wrist_1_trans">
    <type>
      transmission_interface/SimpleTransmission
    </type>
    <joint name="wrist_1_joint">
      <hardwareInterface>
        hardware_interface/PositionJointInterface
      </hardwareInterface>
    </joint>
    <actuator name="wrist_1_motor">
      <mechanicalReduction>
        1
      </mechanicalReduction>
    </actuator>
  </transmission>
  <transmission name="wrist_2_trans">
    <type>
      transmission_interface/SimpleTransmission
    </type>
    <joint name="wrist_2_joint">
      <hardwareInterface>
        hardware_interface/PositionJointInterface
      </hardwareInterface>
    </joint>
    <actuator name="wrist_2_motor">
      <mechanicalReduction>
        1
      </mechanicalReduction>
    </actuator>
  </transmission>
  <transmission name="wrist_3_trans">
    <type>
      transmission_interface/SimpleTransmission
    </type>
    <joint name="wrist_3_joint">
      <hardwareInterface>
        hardware_interface/PositionJointInterface
      </hardwareInterface>
    </joint>
    <actuator name="wrist_3_motor">
      <mechanicalReduction>
        1
      </mechanicalReduction>
    </actuator>
  </transmission>
  <link name="base_link">
    <visual>
      <origin rpy="0 0 3.141592653589793" xyz="0 0 0"/>
      <geometry>
        <mesh filename="../meshes/ur5e/visual/base.dae"/>
      </geometry>
      <material name="LightGrey">
        <color rgba="0.7 0.7 0.7 1.0"/>
      </material>
    </visual>
    <collision>
      <origin rpy="0 0 3.141592653589793" xyz="0 0 0"/>
      <geometry>
        <mesh filename="../meshes/ur5e/collision/base.stl"/>
      </geometry>
    </collision>
    <inertial>
      <mass value="4.0"/>
      <origin rpy="0 0 0" xyz="0 0 0"/>
      <inertia ixx="0.00443333156" ixy="0.0" ixz="0.0" iyy="0.00443333156" iyz="0.0" izz="0.0072"/>
    </inertial>
  </link>
  <link name="shoulder_link">
    <visual>
      <origin rpy="0 0 3.141592653589793" xyz="0 0 0"/>
      <geometry>
        <mesh filename="../meshes/ur5e/visual/shoulder.dae"/>
      </geometry>
      <material name="LightGrey">
        <color rgba="0.7 0.7 0.7 1.0"/>
      </material>
    </visual>
    <collision>
      <origin rpy="0 0 3.141592653589793" xyz="0 0 0"/>
      <geometry>
        <mesh filename="../meshes/ur5e/collision/shoulder.stl"/>
      </geometry>
    </collision>
    <inertial>
      <mass value="3.7"/>
      <origin rpy="0 0 0" xyz="0 0 0"/>
      <inertia ixx="0.010267495893" ixy="0.0" ixz="0.0" iyy="0.010267495893" iyz="0.0" izz="0.00666"/>
    </inertial>
  </link>
  <link name="upper_arm_link">
    <visual>
      <origin rpy="1.5707963267948966 0 -1.5707963267948966" xyz="0 0 0.138"/>
      <geometry>
        <mesh filename="../meshes/ur5e/visual/upperarm.dae"/>
      </geometry>
      <material name="LightGrey">
        <color rgba="0.7 0.7 0.7 1.0"/>
      </material>
    </visual>
    <collision>
      <origin rpy="1.5707963267948966 0 -1.5707963267948966" xyz="0 0 0.138"/>
      <geometry>
        <mesh filename="../meshes/ur5e/collision/upperarm.stl"/>
      </geometry>
    </collision>
    <inertial>
      <mass value="8.393"/>
      <origin rpy="0 1.5707963267948966 0" xyz="-0.2125 0.0 0.138"/>
      <inertia ixx="0.1338857818623325" ixy="0.0" ixz="0.0" iyy="0.1338857818623325" iyz="0.0" izz="0.0151074"/>
    </inertial>
  </link>
  <link name="forearm_link">
    <visual>
      <origin rpy="1.5707963267948966 0 -1.5707963267948966" xyz="0 0 0.007"/>
      <geometry>
        <mesh filename="../meshes/ur5e/visual/forearm.dae"/>
      </geometry>
      <material name="LightGrey">
        <color rgba="0.7 0.7 0.7 1.0"/>
      </material>
    </visual>
    <collision>
      <origin rpy="1.5707963267948966 0 -1.5707963267948966" xyz="0 0 0.007"/>
      <geometry>
        <mesh filename="../meshes/ur5e/collision/forearm.stl"/>
      </geometry>
    </collision>
    <inertial>
      <mass value="2.275"/>
      <origin rpy="0 1.5707963267948966 0" xyz="-0.1961 0.0 0.007"/>
      <inertia ixx="0.031209355099586295" ixy="0.0" ixz="0.0" iyy="0.031209355099586295" iyz="0.0" izz="0.004095"/>
    </inertial>
  </link>
  <link name="wrist_1_link">
    <visual>
      <origin rpy="1.5707963267948966 0 0" xyz="0 0 -0.127"/>
      <geometry>
        <mesh filename="../meshes/ur5e/visual/wrist1.dae"/>
      </geometry>
      <material name="LightGrey">
        <color rgba="0.7 0.7 0.7 1.0"/>
      </material>
    </visual>
    <collision>
      <origin rpy="1.5707963267948966 0 0" xyz="0 0 -0.127"/>
      <geometry>
        <mesh filename="../meshes/ur5e/collision/wrist1.stl"/>
      </geometry>
    </collision>
    <inertial>
      <mass value="1.219"/>
      <origin rpy="0 0 0" xyz="0 0 0"/>
      <inertia ixx="0.0025598989760400002" ixy="0.0" ixz="0.0" iyy="0.0025598989760400002" iyz="0.0" izz="0.0021942"/>
    </inertial>
  </link>
  <link name="wrist_2_link">
    <visual>
      <origin rpy="0 0 0" xyz="0 0 -0.0997"/>
      <geometry>
        <mesh filename="../meshes/ur5e/visual/wrist2.dae"/>
      </geometry>
      <material name="LightGrey">
        <color rgba="0.7 0.7 0.7 1.0"/>
      </material>
    </visual>
    <collision>
      <origin rpy="0 0 0" xyz="0 0 -0.0997"/>
      <geometry>
        <mesh filename="../meshes/ur5e/collision/wrist2.stl"/>
      </geometry>
    </collision>
    <inertial>
      <mass value="1.219"/>
      <origin rpy="0 0 0" xyz="0 0 0"/>
      <inertia ixx="0.0025598989760400002" ixy="0.0" ixz="0.0" iyy="0.0025598989760400002" iyz="0.0" izz="0.0021942"/>
    </inertial>
  </link>
  <link name="wrist_3_link">
    <visual>
      <origin rpy="1.5707963267948966 0 0" xyz="0 0 -0.0989"/>
      <geometry>
        <mesh filename="../meshes/ur5e/visual/wrist3.dae"/>
      </geometry>
      <material name="LightGrey">
        <color rgba="0.7 0.7 0.7 1.0"/>
      </material>
    </visual>
    <collision>
      <origin rpy="1.5707963267948966 0 0" xyz="0 0 -0.0989"/>
      <geometry>
        <mesh filename="../meshes/ur5e/collision/wrist3.stl"/>
      </geometry>
    </collision>
    <inertial>
      <mass value="0.1879"/>
      <origin rpy="0 0 0" xyz="0.0 0.0 -0.0229"/>
      <inertia ixx="9.890410052167731e-05" ixy="0.0" ixz="0.0" iyy="9.890410052167731e-05" iyz="0.0" izz="0.0001321171875"/>
    </inertial>
  </link>
  <joint name="shoulder_pan_joint" type="revolute">
    <parent link="base_link"/>
    <child link="shoulder_link"/>
    <origin rpy="0 0 5.838799881086043e-08" xyz="0 0 0.1627957511460952"/>
    <axis xyz="0 0 1"/>
    <limit effort="150.0" lower="-6.283185307179586" upper="6.283185307179586" velocity="3.141592653589793"/>
    <dynamics damping="0" friction="0"/>
  </joint>
  <joint name="shoulder_lift_joint" type="revolute">
    <parent link="shoulder_link"/>
    <child link="upper_arm_link"/>
    <origin rpy="1.571121456180029 0 3.408471391117692e-06" xyz="0.0002297527990250293 0 0"/>
    <axis xyz="0 0 1"/>
    <limit effort="150.0" lower="-6.283185307179586" upper="6.283185307179586" velocity="3.141592653589793"/>
    <dynamics damping="0" friction="0"/>
  </joint>
  <joint name="elbow_joint" type="revolute">
    <parent link="upper_arm_link"/>
    <child link="forearm_link"/>
    <origin rpy="3.141560008571467 -3.140442251338941 -3.141590660002632" xyz="-0.4251778979556664 0 0"/>
    <axis xyz="0 0 1"/>
    <limit effort="150.0" lower="-3.141592653589793" upper="3.141592653589793" velocity="3.141592653589793"/>
    <dynamics damping="0" friction="0"/>
  </joint>
  <joint name="wrist_1_joint" type="revolute">
    <parent link="forearm_link"/>
    <child link="wrist_1_link"/>
    <origin rpy="0.005348319422639594 0.0007457898627076391 -9.589521419945506e-06" xyz="-0.3922529717389943 -0.0007143311192542647 0.1335605171943241"/>
    <axis xyz="0 0 1"/>
    <limit effort="28.0" lower="-6.283185307179586" upper="6.283185307179586" velocity="3.141592653589793"/>
    <dynamics damping="0" friction="0"/>
  </joint>
  <joint name="wrist_2_joint" type="revolute">
    <parent link="wrist_1_link"/>
    <child link="wrist_2_link"/>
    <origin rpy="1.569002492985847 0 2.722422549790438e-07" xyz="1.071549191182041e-05 -0.09981515817881177 0.0001790519974503692"/>
    <axis xyz="0 0 1"/>
    <limit effort="28.0" lower="-6.283185307179586" upper="6.283185307179586" velocity="3.141592653589793"/>
    <dynamics damping="0" friction="0"/>
  </joint>
  <joint name="wrist_3_joint" type="revolute">
    <parent link="wrist_2_link"/>
    <child link="wrist_3_link"/>
    <origin rpy="1.570920213539041 3.141592653589793 3.141592608469836" xyz="2.427717241733769e-05 0.0996119808551117 1.234060404910167e-05"/>
    <axis xyz="0 0 1"/>
    <limit effort="28.0" lower="-6.283185307179586" upper="6.283185307179586" velocity="3.141592653589793"/>
    <dynamics damping="0" friction="0"/>
  </joint>

  <joint name="flange_camera_flange_joint" type="fixed">
    <parent link="flange"/>
    <child link="camera_wrist_mount"/>
    <origin rpy="0 0 0" xyz="0.000 0.000 0.00"/>
  </joint>
  <link name="camera_wrist_mount">
    <visual>
      <origin xyz="0.0 0 0.015" rpy="0 1.570796327 -1.570796327 "/>
      <geometry>
        <mesh filename="../meshes/camera/wrist_mount.stl"/>
      </geometry>
    </visual>
    <collision>
      <origin rpy="0 0 0" xyz="0.0 -0.02 0.0075"/>
      <geometry>
          <box size="0.055 0.11 0.015"/>
      </geometry>
    </collision>
    <inertial>
      <origin rpy="0.00 0.00 0.00" xyz="0.061902 0.000129 -0.000005"/>
      <mass value="1.684558"/>
      <inertia ixx="0.000862" ixy="0.000000" ixz="0.000000" iyy="0.002401" iyz="-0.000001" izz="0.002620"/>
    </inertial>
  </link>
  <joint name="camera_wrist_mount_mount2_fixed_joint" type="fixed">
    <parent link="camera_wrist_mount"/>
    <child link="camera_and_mount"/>
    <origin rpy="0 0 0" xyz="0.0 -0.0625 0.0"/>
  </joint>
  <link name="camera_and_mount">
    <visual>
      <origin rpy="0 -1.570796327 1.570796327" xyz="0.0 0.0 0.0075"/>
      <geometry>
          <mesh filename="../meshes/camera/simple_basler_with_mount.stl"/>
      </geometry>
    </visual>
    <collision>
      <origin rpy="0 0 0" xyz="0.0 -0.025 0.03"/>
      <geometry>
          <box size="0.05 0.05 0.16"/>
      </geometry>
    </collision>
    <inertial>
      <origin rpy="0.00 0.00 0.00" xyz="0.061902 0.000129 -0.000005"/>
      <mass value="1.684558"/>
      <inertia ixx="0.000862" ixy="0.000000" ixz="0.000000" iyy="0.002401" iyz="-0.000001" izz="0.002620"/>
    </inertial>
  </link>
  <link name="gripper_base_link"/>
  <joint name="gripper_base_link_hand_link_fixed_joint" type="fixed">
    <parent link="gripper_base_link"/>
    <child link="hand_link"/>
    <origin rpy="0 0 0" xyz="0.0 0.000 0.000"/>
  </joint>
  <link name="hand_link">
    <collision>
      <origin rpy="0.00 0.00 0.00" xyz="0.00 0.00 0.00"/>
      <geometry>
        <mesh filename="../meshes/gripper_onrobot_rg2/collision/RG2_Hand_col.STL"/>
      </geometry>
    </collision>
    <visual>
      <origin rpy="0.00 0.00 0.00" xyz="0.00 0.00 0.00"/>
      <geometry>
        <mesh filename="../meshes/gripper_onrobot_rg2/visual/RG2_Hand_vis.STL"/>
      </geometry>
    </visual>
    <inertial>
      <origin rpy="0.00 0.00 0.00" xyz="0.061902 0.000129 -0.000005"/>
      <mass value="1.684558"/>
      <inertia ixx="0.000862" ixy="0.000000" ixz="0.000000" iyy="0.002401" iyz="-0.000001" izz="0.002620"/>
    </inertial>
  </link>
  <joint name="l_moment_arm_joint" type="revolute">
    <parent link="hand_link"/>
    <child link="l_moment_arm_link"/>
    <origin rpy="0 0 0" xyz="0.132 0.017 0.010"/>
    <axis xyz="0 0 1"/>
    <limit effort="10.6" lower="-0.45" upper="1.570796327" velocity="3.14"/>
    <dynamics damping="0.1" friction="0.0"/>
    <implicitSpringDamper>
      True
    </implicitSpringDamper>
  </joint>
  <transmission name="l_moment_arm_joint_tran">
    <type>
      transmission_interface/SimpleTransmission
    </type>
    <joint name="l_moment_arm_joint">
      <hardwareInterface>
        hardware_interface/EffortJointInterface
      </hardwareInterface>
    </joint>
    <actuator name="l_moment_arm_joint_motor">
      <hardwareInterface>
        hardware_interface/EffortJointInterface
      </hardwareInterface>
      <mechanicalReduction>
        1
      </mechanicalReduction>
    </actuator>
  </transmission>
  <link name="l_moment_arm_link">
    <collision>
      <origin rpy="0.00 0.00 0.00" xyz="0.00 0.00 0.00"/>
      <geometry>
        <mesh filename="../meshes/gripper_onrobot_rg2/collision/RG2_LeftMomentArm_col.STL"/>
      </geometry>
    </collision>
    <visual>
      <origin rpy="0.00 0.00 0.00" xyz="0.00 0.00 0.00"/>
      <geometry>
        <mesh filename="../meshes/gripper_onrobot_rg2/visual/RG2_LeftMomentArm_vis.STL"/>
      </geometry>
    </visual>
    <inertial>
      <origin rpy="0.00 0.00 0.00" xyz="0.017004 0.006397 -0.010300"/>
      <mass value="0.160209"/>
      <inertia ixx="0.000023" ixy="0.000019" ixz="0.000000" iyy="0.000072" iyz="0.000000" izz="0.000083"/>
    </inertial>
  </link>
  <joint name="l_finger_2_joint" type="revolute">
    <parent link="l_moment_arm_link"/>
    <child link="l_finger_link"/>
    <origin rpy="0 0 0" xyz="0.049 0.026 0.000"/>
    <axis xyz="0 0 1"/>
    <limit effort="10.6" lower="-1.570796327" upper="1.570796327" velocity="3.14"/>
    <dynamics damping="0.1" friction="0.0"/>
    <implicitSpringDamper>
      True
    </implicitSpringDamper>
  </joint>
  <transmission name="l_finger_2_joint_tran">
    <type>
      transmission_interface/SimpleTransmission
    </type>
    <joint name="l_finger_2_joint">
      <hardwareInterface>
        hardware_interface/EffortJointInterface
      </hardwareInterface>
    </joint>
    <actuator name="l_finger_2_joint_motor">
      <hardwareInterface>
        hardware_interface/EffortJointInterface
      </hardwareInterface>
      <mechanicalReduction>
        1
      </mechanicalReduction>
    </actuator>
  </transmission>
  <link name="l_finger_link">
    <collision>
      <origin rpy="0.00 0.00 0.00" xyz="0.00 0.00 0.00"/>
      <geometry>
        <mesh filename="../meshes/gripper_onrobot_rg2/collision/RG2_LeftFinger_col.STL"/>
      </geometry>
      <collision_margin value="0.001"/>
    </collision>
    <visual>
      <origin rpy="0.00 0.00 0.00" xyz="0.00 0.00 0.00"/>
      <geometry>
        <mesh filename="../meshes/gripper_onrobot_rg2/visual/RG2_LeftFinger_vis.STL"/>
      </geometry>
    </visual>
    <inertial>
      <origin rpy="0.00 0.00 0.00" xyz="0.024695 -0.010178 -0.010001"/>
      <mass value="0.081638"/>
      <inertia ixx="0.000006" ixy="-0.000005" ixz="0.000000" iyy="0.000025" iyz="0.000000" izz="0.000026"/>
    </inertial>
  </link>
  <joint name="l_finger_passive_joint" type="revolute">
    <parent link="l_finger_link"/>
    <child link="l_truss_arm_link"/>
    <origin rpy="0 0 0" xyz="0.0165 -0.0093 0.0"/>
    <axis xyz="0 0 1"/>
    <limit effort="10.6" lower="-1.570796327" upper="1.570796327" velocity="3.14"/>
    <dynamics damping="0.1" friction="0.0"/>
    <implicitSpringDamper>
      True
    </implicitSpringDamper>
  </joint>
  <transmission name="l_finger_passive_joint_tran">
    <type>
      transmission_interface/SimpleTransmission
    </type>
    <joint name="l_finger_passive_joint">
      <hardwareInterface>
        hardware_interface/EffortJointInterface
      </hardwareInterface>
    </joint>
    <actuator name="l_finger_passive_joint_motor">
      <hardwareInterface>
        hardware_interface/EffortJointInterface
      </hardwareInterface>
      <mechanicalReduction>
        1
      </mechanicalReduction>
    </actuator>
  </transmission>
  <link name="l_truss_arm_link">
    <collision>
      <origin rpy="0.00 0.00 0.00" xyz="-0.0487 -0.0258 0.00"/>
      <geometry>
        <mesh filename="../meshes/gripper_onrobot_rg2/collision/RG2_LeftTrussArm_col.STL"/>
      </geometry>
    </collision>
    <visual>
      <origin rpy="0.00 0.00 0.00" xyz="-0.0487 -0.0258 0.00"/>
      <geometry>
        <mesh filename="../meshes/gripper_onrobot_rg2/visual/RG2_LeftTrussArm_vis.STL"/>
      </geometry>
    </visual>
    <inertial>
      <origin rpy="0.00 0.00 0.00" xyz="0.023075 0.012136 -0.010000"/>
      <mass value="0.065927"/>
      <inertia ixx="0.000010" ixy="0.000010" ixz="0.000000" iyy="0.000024" iyz="0.000000" izz="0.000025"/>
    </inertial>
  </link>
  <joint name="r_finger_1_joint" type="revolute">
    <parent link="hand_link"/>
    <child link="r_moment_arm_link"/>
    <origin rpy="0 0 0" xyz="0.132 -0.017 0.010"/>
    <axis xyz="0 0 1"/>
    <limit effort="10.6" lower="-1.570796327" upper="1.570796327" velocity="3.14"/>
    <dynamics damping="0.1" friction="0.0"/>
    <implicitSpringDamper>
      True
    </implicitSpringDamper>
  </joint>
  <transmission name="r_finger_1_joint_tran">
    <type>
      transmission_interface/SimpleTransmission
    </type>
    <joint name="r_finger_1_joint">
      <hardwareInterface>
        hardware_interface/EffortJointInterface
      </hardwareInterface>
    </joint>
    <actuator name="r_finger_1_joint_motor">
      <hardwareInterface>
        hardware_interface/EffortJointInterface
      </hardwareInterface>
      <mechanicalReduction>
        1
      </mechanicalReduction>
    </actuator>
  </transmission>
  <link name="r_moment_arm_link">
    <collision>
      <origin rpy="0.00 0.00 0.00" xyz="0.00 0.00 0.00"/>
      <geometry>
        <mesh filename="../meshes/gripper_onrobot_rg2/collision/RG2_RightMomentArm_col.STL"/>
      </geometry>
    </collision>
    <visual>
      <origin rpy="0.00 0.00 0.00" xyz="0.00 0.00 0.00"/>
      <geometry>
        <mesh filename="../meshes/gripper_onrobot_rg2/visual/RG2_RightMomentArm_vis.STL"/>
      </geometry>
    </visual>
    <inertial>
      <origin rpy="0.00 0.00 0.00" xyz="0.017004 -0.006397 -0.010300"/>
      <mass value="0.160209"/>
      <inertia ixx="0.000023" ixy="-0.000019" ixz="0.000000" iyy="0.000072" iyz="0.000000" izz="0.000083"/>
    </inertial>
  </link>
  <joint name="r_finger_2_joint" type="revolute">
    <parent link="r_moment_arm_link"/>
    <child link="r_finger_link"/>
    <origin rpy="0 0 0" xyz="0.049 -0.026 0.000"/>
    <axis xyz="0 0 1"/>
    <limit effort="10.6" lower="-1.570796327" upper="1.570796327" velocity="3.14"/>
    <dynamics damping="0.1" friction="0.0"/>
    <implicitSpringDamper>
      True
    </implicitSpringDamper>
  </joint>
  <transmission name="r_finger_2_joint_tran">
    <type>
      transmission_interface/SimpleTransmission
    </type>
    <joint name="r_finger_2_joint">
      <hardwareInterface>
        hardware_interface/EffortJointInterface
      </hardwareInterface>
    </joint>
    <actuator name="r_finger_2_joint_motor">
      <hardwareInterface>
        hardware_interface/EffortJointInterface
      </hardwareInterface>
      <mechanicalReduction>
        1
      </mechanicalReduction>
    </actuator>
  </transmission>
  <link name="r_finger_link">
    <collision>
      <origin rpy="0.00 0.00 0.00" xyz="0.00 0.00 0.00"/>
      <geometry>
        <mesh filename="../meshes/gripper_onrobot_rg2/collision/RG2_RightFinger_col.STL"/>
      </geometry>
      <collision_margin value="0.001"/>
    </collision>
    <visual>
      <origin rpy="0.00 0.00 0.00" xyz="0.00 0.00 0.00"/>
      <geometry>
        <mesh filename="../meshes/gripper_onrobot_rg2/visual/RG2_RightFinger_vis.STL"/>
      </geometry>
    </visual>
    <inertial>
      <origin rpy="0.00 0.00 0.00" xyz="0.024695 0.010178 -0.010000"/>
      <mass value="0.081637"/>
      <inertia ixx="0.000006" ixy="0.000005" ixz="0.000000" iyy="0.000025" iyz="0.000000" izz="0.000026"/>
    </inertial>
  </link>
  <joint name="r_finger_passive_joint" type="revolute">
    <parent link="r_finger_link"/>
    <child link="r_truss_arm_link"/>
    <origin rpy="0 0 0" xyz="0.0165 0.0093 0.0"/>
    <axis xyz="0 0 1"/>
    <limit effort="10.6" lower="-1.570796327" upper="1.570796327" velocity="3.14"/>
    <dynamics damping="0.1" friction="0.0"/>
    <implicitSpringDamper>
      True
    </implicitSpringDamper>
  </joint>
  <transmission name="r_finger_passive_joint_tran">
    <type>
      transmission_interface/SimpleTransmission
    </type>
    <joint name="r_finger_passive_joint">
      <hardwareInterface>
        hardware_interface/EffortJointInterface
      </hardwareInterface>
    </joint>
    <actuator name="r_finger_passive_joint_motor">
      <hardwareInterface>
        hardware_interface/EffortJointInterface
      </hardwareInterface>
      <mechanicalReduction>
        1
      </mechanicalReduction>
    </actuator>
  </transmission>
  <link name="r_truss_arm_link">
    <collision>
      <origin rpy="0.00 0.00 0.00" xyz="-0.0487 0.0258 0.00"/>
      <geometry>
        <mesh filename="../meshes/gripper_onrobot_rg2/collision/RG2_RightTrussArm_col.STL"/>
      </geometry>
    </collision>
    <visual>
      <origin rpy="0.00 0.00 0.00" xyz="-0.0487 0.0258 0.00"/>
      <geometry>
        <mesh filename="../meshes/gripper_onrobot_rg2/visual/RG2_RightTrussArm_vis.STL"/>
      </geometry>
    </visual>
    <inertial>
      <origin rpy="0.00 0.00 0.00" xyz="0.023075 -0.012136 -0.010000"/>
      <mass value="0.065927"/>
      <inertia ixx="0.000010" ixy="-0.000010" ixz="0.000000" iyy="0.000024" iyz="0.000000" izz="0.000025"/>
    </inertial>
  </link>
  <joint name="flange-rg2" type="fixed">
    <origin rpy="3.141592653589793 -1.5707963267948966 -1.5707963267948966" xyz="0.0 0 0.0155"/>
    <parent link="flange"/>
    <child link="gripper_base_link"/>
  </joint>
  <link name="flange"/>
  <joint name="wrist_3-flange" type="fixed">
    <parent link="wrist_3_link"/>
    <child link="flange"/>
    <origin rpy="0 0 0" xyz="0 0 0"/>
  </joint>
  <link name="tcp">
  </link>
  <link name="tcp_extension">
  </link>
  <joint name="tcp-tcp_extension" type="fixed">
    <origin rpy="0 0 0" xyz="0 0 0.2"/>
    <parent link="tcp"/>
    <child link="tcp_extension"/>
  </joint>
  <joint name="flange-tcp" type="fixed">
    <origin rpy="0 0 0" xyz="0 0 0.223"/>
    <parent link="flange"/>
    <child link="tcp"/>
  </joint>
  <link name="world"/>
  <joint name="world_joint" type="fixed">
    <parent link="world"/>
    <child link="base_link"/>
    <origin rpy="0.0 0.0 0.0" xyz="0.0 0.0 0.0"/>
  </joint>
</robot>